[restart_app] Repo root: C:\Dev\Gold\gchub_db
[restart_app] Looking for processes listening on port 8000...
[restart_app] No processes found on port 8000.
[restart_app] Starting local Postgres via docker-compose (if not already running)...
 Container dev-postgres-1  Recreate
 Container dev-postgres-1  Recreated
 Container dev-postgres-1  Starting
 Container dev-postgres-1  Started
[restart_app] Postgres container id: f543df200414005c90b308a01a8b796fb8f7d7497ac36012c750e879e91029a3
[restart_app] Postgres ready
[restart_app] Skipping destructive repo clean (pass -CleanRepo to enable).
[restart_app] Removing .pyc files and __pycache__ directories...
[restart_app] Attempting to clear Django cache...
C:\Dev\Gold\gchub_db\.venv\Lib\site-packages\gntp\core.py:22: SyntaxWarning: invalid escape sequence '\d'
  'GNTP/(?P<version>\d+\.\d+) (?P<messagetype>REGISTER|NOTIFY|SUBSCRIBE|\-OK|\-ERROR)' +
C:\Dev\Gold\gchub_db\.venv\Lib\site-packages\gntp\core.py:29: SyntaxWarning: invalid escape sequence '\d'
  'GNTP/(?P<version>\d+\.\d+) (?P<messagetype>REGISTER|NOTIFY|SUBSCRIBE|\-OK|\-ERROR)',
C:\Dev\Gold\gchub_db\.venv\Lib\site-packages\gntp\core.py:33: SyntaxWarning: invalid escape sequence '\w'
  GNTP_HEADER = re.compile('([\w-]+):(.+)')
C:\Dev\Gold\gchub_db\.venv\Lib\site-packages\colormath\color_conversions.py:40: SyntaxWarning: invalid escape sequence '\*'
  logger.debug("  \* Applying RGB conversion matrix: %s->%s",
C:\Dev\Gold\gchub_db\.venv\Lib\site-packages\colormath\color_conversions.py:488: SyntaxWarning: invalid escape sequence '\-'
  logger.debug("  \- Target RGB space: %s", target_rgb)
C:\Dev\Gold\gchub_db\.venv\Lib\site-packages\colormath\color_conversions.py:490: SyntaxWarning: invalid escape sequence '\-'
  logger.debug("  \- Target native illuminant: %s", target_illum)
C:\Dev\Gold\gchub_db\.venv\Lib\site-packages\colormath\color_conversions.py:491: SyntaxWarning: invalid escape sequence '\-'
  logger.debug("  \- XYZ color's illuminant: %s", cobj.illuminant)
C:\Dev\Gold\gchub_db\.venv\Lib\site-packages\colormath\color_conversions.py:497: SyntaxWarning: invalid escape sequence '\*'
  logger.debug("  \* Applying transformation from %s to %s ",
C:\Dev\Gold\gchub_db\.venv\Lib\site-packages\colormath\color_conversions.py:503: SyntaxWarning: invalid escape sequence '\*'
  logger.debug("  \*   New values: %.3f, %.3f, %.3f",
C:\Dev\Gold\gchub_db\.venv\Lib\site-packages\colormath\color_objects.py:452: SyntaxWarning: invalid escape sequence '\-'
  logger.debug("  \- Original illuminant: %s", self.illuminant)
C:\Dev\Gold\gchub_db\.venv\Lib\site-packages\colormath\color_objects.py:453: SyntaxWarning: invalid escape sequence '\-'
  logger.debug("  \- Target illuminant: %s", target_illuminant)
C:\Dev\Gold\gchub_db\.venv\Lib\site-packages\colormath\color_objects.py:459: SyntaxWarning: invalid escape sequence '\*'
  logger.debug("  \* Applying transformation from %s to %s ",
C:\Dev\Gold\gchub_db\.venv\Lib\site-packages\colormath\chromatic_adaptation.py:85: SyntaxWarning: invalid escape sequence '\*'
  logger.debug("  \* Applying adaptation matrix: %s", adaptation)
2025-09-01 18:38:12 DEBUG    2025-09-01 18:38:12 [DEBUG]          fsb_box.py:27
                             gchub_db.apps.auto_corrugated.docume
                             nts.fsb_box: Font file not found at:
                             /mnt\Production\autocorr_elements\VA
                             G Rounded BT.ttf
cache cleared
[restart_app] Ensuring dev DB user and database (dev\ensure_gchub.py)...
Connected to Postgres at 127.0.0.1:5432 as postgres
Role 'gchub' already exists
Updated password for role 'gchub'
Database 'gchub_dev' already exists
Granting privileges on database 'gchub_dev' to 'gchub'
Privileges granted (best-effort)
ensure_gchub completed successfully
[restart_app] Running migrations...
2025-09-01 18:38:14 DEBUG    2025-09-01 18:38:14 [DEBUG]          fsb_box.py:27
                             gchub_db.apps.auto_corrugated.docume
                             nts.fsb_box: Font file not found at:
                             /mnt\Production\autocorr_elements\VA
                             G Rounded BT.ttf
[31;1mTraceback (most recent call last):[0m
[31;1m  File "C:\Dev\Gold\gchub_db\.venv\Lib\site-packages\django\db\backends\base\base.py", line 279, in ensure_connection[0m
[31;1m    self.connect()[0m
[31;1m    ~~~~~~~~~~~~^^[0m
[31;1m  File "C:\Dev\Gold\gchub_db\.venv\Lib\site-packages\django\utils\asyncio.py", line 26, in inner[0m
[31;1m    return func(*args, **kwargs)[0m
[31;1m  File "C:\Dev\Gold\gchub_db\.venv\Lib\site-packages\django\db\backends\base\base.py", line 256, in connect[0m
[31;1m    self.connection = self.get_new_connection(conn_params)[0m
[31;1m                      ~~~~~~~~~~~~~~~~~~~~~~~^^^^^^^^^^^^^[0m
[31;1m  File "C:\Dev\Gold\gchub_db\.venv\Lib\site-packages\django\utils\asyncio.py", line 26, in inner[0m
[31;1m    return func(*args, **kwargs)[0m
[31;1m  File "C:\Dev\Gold\gchub_db\.venv\Lib\site-packages\django\db\backends\postgresql\base.py", line 332, in get_new_connection[0m
[31;1m    connection = self.Database.connect(**conn_params)[0m
[31;1m  File "C:\Dev\Gold\gchub_db\.venv\Lib\site-packages\psycopg2\__init__.py", line 135, in connect[0m
[31;1m    conn = _connect(dsn, connection_factory=connection_factory, **kwasync)[0m
[31;1mpsycopg2.OperationalError: connection to server at "172.23.8.73", port 5432 failed: Connection timed out (0x0000274C/10060)[0m
[31;1m	Is the server running on that host and accepting TCP/IP connections?[0m
[31;1m[0m
[31;1m[0m
[31;1mThe above exception was the direct cause of the following exception:[0m
[31;1m[0m
[31;1mTraceback (most recent call last):[0m
[31;1m  File "C:\Dev\Gold\gchub_db\manage.py", line 37, in <module>[0m
[31;1m    execute_from_command_line(sys.argv)[0m
[31;1m    ~~~~~~~~~~~~~~~~~~~~~~~~~^^^^^^^^^^[0m
[31;1m  File "C:\Dev\Gold\gchub_db\.venv\Lib\site-packages\django\core\management\__init__.py", line 442, in execute_from_command_line[0m
[31;1m    utility.execute()[0m
[31;1m    ~~~~~~~~~~~~~~~^^[0m
[31;1m  File "C:\Dev\Gold\gchub_db\.venv\Lib\site-packages\django\core\management\__init__.py", line 436, in execute[0m
[31;1m    self.fetch_command(subcommand).run_from_argv(self.argv)[0m
[31;1m    ~~~~~~~~~~~~~~~~~~~~~~~~~~~~~~~~~~~~~~~~~~~~^^^^^^^^^^^[0m
[31;1m  File "C:\Dev\Gold\gchub_db\.venv\Lib\site-packages\django\core\management\base.py", line 416, in run_from_argv[0m
[31;1m    self.execute(*args, **cmd_options)[0m
[31;1m    ~~~~~~~~~~~~^^^^^^^^^^^^^^^^^^^^^^[0m
[31;1m  File "C:\Dev\Gold\gchub_db\.venv\Lib\site-packages\django\core\management\base.py", line 460, in execute[0m
[31;1m    output = self.handle(*args, **options)[0m
[31;1m  File "C:\Dev\Gold\gchub_db\.venv\Lib\site-packages\django\core\management\base.py", line 107, in wrapper[0m
[31;1m    res = handle_func(*args, **kwargs)[0m
[31;1m  File "C:\Dev\Gold\gchub_db\.venv\Lib\site-packages\django\core\management\commands\migrate.py", line 114, in handle[0m
[31;1m    executor = MigrationExecutor(connection, self.migration_progress_callback)[0m
[31;1m  File "C:\Dev\Gold\gchub_db\.venv\Lib\site-packages\django\db\migrations\executor.py", line 18, in __init__[0m
[31;1m    self.loader = MigrationLoader(self.connection)[0m
[31;1m                  ~~~~~~~~~~~~~~~^^^^^^^^^^^^^^^^^[0m
[31;1m  File "C:\Dev\Gold\gchub_db\.venv\Lib\site-packages\django\db\migrations\loader.py", line 58, in __init__[0m
[31;1m    self.build_graph()[0m
[31;1m    ~~~~~~~~~~~~~~~~^^[0m
[31;1m  File "C:\Dev\Gold\gchub_db\.venv\Lib\site-packages\django\db\migrations\loader.py", line 235, in build_graph[0m
[31;1m    self.applied_migrations = recorder.applied_migrations()[0m
[31;1m                              ~~~~~~~~~~~~~~~~~~~~~~~~~~~^^[0m
[31;1m  File "C:\Dev\Gold\gchub_db\.venv\Lib\site-packages\django\db\migrations\recorder.py", line 89, in applied_migrations[0m
[31;1m    if self.has_table():[0m
[31;1m       ~~~~~~~~~~~~~~^^[0m
[31;1m  File "C:\Dev\Gold\gchub_db\.venv\Lib\site-packages\django\db\migrations\recorder.py", line 63, in has_table[0m
[31;1m    with self.connection.cursor() as cursor:[0m
[31;1m         ~~~~~~~~~~~~~~~~~~~~~~^^[0m
[31;1m  File "C:\Dev\Gold\gchub_db\.venv\Lib\site-packages\django\utils\asyncio.py", line 26, in inner[0m
[31;1m    return func(*args, **kwargs)[0m
[31;1m  File "C:\Dev\Gold\gchub_db\.venv\Lib\site-packages\django\db\backends\base\base.py", line 320, in cursor[0m
[31;1m    return self._cursor()[0m
[31;1m           ~~~~~~~~~~~~^^[0m
[31;1m  File "C:\Dev\Gold\gchub_db\.venv\Lib\site-packages\django\db\backends\base\base.py", line 296, in _cursor[0m
[31;1m    self.ensure_connection()[0m
[31;1m    ~~~~~~~~~~~~~~~~~~~~~~^^[0m
[31;1m  File "C:\Dev\Gold\gchub_db\.venv\Lib\site-packages\django\utils\asyncio.py", line 26, in inner[0m
[31;1m    return func(*args, **kwargs)[0m
[31;1m  File "C:\Dev\Gold\gchub_db\.venv\Lib\site-packages\django\db\backends\base\base.py", line 278, in ensure_connection[0m
[31;1m    with self.wrap_database_errors:[0m
[31;1m         ^^^^^^^^^^^^^^^^^^^^^^^^^[0m
[31;1m  File "C:\Dev\Gold\gchub_db\.venv\Lib\site-packages\django\db\utils.py", line 91, in __exit__[0m
[31;1m    raise dj_exc_value.with_traceback(traceback) from exc_value[0m
[31;1m  File "C:\Dev\Gold\gchub_db\.venv\Lib\site-packages\django\db\backends\base\base.py", line 279, in ensure_connection[0m
[31;1m    self.connect()[0m
[31;1m    ~~~~~~~~~~~~^^[0m
[31;1m  File "C:\Dev\Gold\gchub_db\.venv\Lib\site-packages\django\utils\asyncio.py", line 26, in inner[0m
[31;1m    return func(*args, **kwargs)[0m
[31;1m  File "C:\Dev\Gold\gchub_db\.venv\Lib\site-packages\django\db\backends\base\base.py", line 256, in connect[0m
[31;1m    self.connection = self.get_new_connection(conn_params)[0m
[31;1m                      ~~~~~~~~~~~~~~~~~~~~~~~^^^^^^^^^^^^^[0m
[31;1m  File "C:\Dev\Gold\gchub_db\.venv\Lib\site-packages\django\utils\asyncio.py", line 26, in inner[0m
[31;1m    return func(*args, **kwargs)[0m
[31;1m  File "C:\Dev\Gold\gchub_db\.venv\Lib\site-packages\django\db\backends\postgresql\base.py", line 332, in get_new_connection[0m
[31;1m    connection = self.Database.connect(**conn_params)[0m
[31;1m  File "C:\Dev\Gold\gchub_db\.venv\Lib\site-packages\psycopg2\__init__.py", line 135, in connect[0m
[31;1m    conn = _connect(dsn, connection_factory=connection_factory, **kwasync)[0m
[31;1mdjango.db.utils.OperationalError: connection to server at "172.23.8.73", port 5432 failed: Connection timed out (0x0000274C/10060)[0m
[31;1m	Is the server running on that host and accepting TCP/IP connections?[0m
[31;1m[0m
[restart_app] Detected DB errors in migrate output; aborting server start.
[restart_app] --- Tail of dev\migrate_output.txt ---
2025-09-01 18:38:14 DEBUG    2025-09-01 18:38:14 [DEBUG]          fsb_box.py:27
                             gchub_db.apps.auto_corrugated.docume
                             nts.fsb_box: Font file not found at:
                             /mnt\Production\autocorr_elements\VA
                             G Rounded BT.ttf
Traceback (most recent call last):
  File "C:\Dev\Gold\gchub_db\.venv\Lib\site-packages\django\db\backends\base\base.py", line 279, in ensure_connection
    self.connect()
    ~~~~~~~~~~~~^^
  File "C:\Dev\Gold\gchub_db\.venv\Lib\site-packages\django\utils\asyncio.py", line 26, in inner
    return func(*args, **kwargs)
  File "C:\Dev\Gold\gchub_db\.venv\Lib\site-packages\django\db\backends\base\base.py", line 256, in connect
    self.connection = self.get_new_connection(conn_params)
                      ~~~~~~~~~~~~~~~~~~~~~~~^^^^^^^^^^^^^
  File "C:\Dev\Gold\gchub_db\.venv\Lib\site-packages\django\utils\asyncio.py", line 26, in inner
    return func(*args, **kwargs)
  File "C:\Dev\Gold\gchub_db\.venv\Lib\site-packages\django\db\backends\postgresql\base.py", line 332, in get_new_connection
    connection = self.Database.connect(**conn_params)
  File "C:\Dev\Gold\gchub_db\.venv\Lib\site-packages\psycopg2\__init__.py", line 135, in connect
    conn = _connect(dsn, connection_factory=connection_factory, **kwasync)
psycopg2.OperationalError: connection to server at "172.23.8.73", port 5432 failed: Connection timed out (0x0000274C/10060)
	Is the server running on that host and accepting TCP/IP connections?


The above exception was the direct cause of the following exception:

Traceback (most recent call last):
  File "C:\Dev\Gold\gchub_db\manage.py", line 37, in <module>
    execute_from_command_line(sys.argv)
    ~~~~~~~~~~~~~~~~~~~~~~~~~^^^^^^^^^^
  File "C:\Dev\Gold\gchub_db\.venv\Lib\site-packages\django\core\management\__init__.py", line 442, in execute_from_command_line
    utility.execute()
    ~~~~~~~~~~~~~~~^^
  File "C:\Dev\Gold\gchub_db\.venv\Lib\site-packages\django\core\management\__init__.py", line 436, in execute
    self.fetch_command(subcommand).run_from_argv(self.argv)
    ~~~~~~~~~~~~~~~~~~~~~~~~~~~~~~~~~~~~~~~~~~~~^^^^^^^^^^^
  File "C:\Dev\Gold\gchub_db\.venv\Lib\site-packages\django\core\management\base.py", line 416, in run_from_argv
    self.execute(*args, **cmd_options)
    ~~~~~~~~~~~~^^^^^^^^^^^^^^^^^^^^^^
  File "C:\Dev\Gold\gchub_db\.venv\Lib\site-packages\django\core\management\base.py", line 460, in execute
    output = self.handle(*args, **options)
  File "C:\Dev\Gold\gchub_db\.venv\Lib\site-packages\django\core\management\base.py", line 107, in wrapper
    res = handle_func(*args, **kwargs)
  File "C:\Dev\Gold\gchub_db\.venv\Lib\site-packages\django\core\management\commands\migrate.py", line 114, in handle
    executor = MigrationExecutor(connection, self.migration_progress_callback)
  File "C:\Dev\Gold\gchub_db\.venv\Lib\site-packages\django\db\migrations\executor.py", line 18, in __init__
    self.loader = MigrationLoader(self.connection)
                  ~~~~~~~~~~~~~~~^^^^^^^^^^^^^^^^^
  File "C:\Dev\Gold\gchub_db\.venv\Lib\site-packages\django\db\migrations\loader.py", line 58, in __init__
    self.build_graph()
    ~~~~~~~~~~~~~~~~^^
  File "C:\Dev\Gold\gchub_db\.venv\Lib\site-packages\django\db\migrations\loader.py", line 235, in build_graph
    self.applied_migrations = recorder.applied_migrations()
                              ~~~~~~~~~~~~~~~~~~~~~~~~~~~^^
  File "C:\Dev\Gold\gchub_db\.venv\Lib\site-packages\django\db\migrations\recorder.py", line 89, in applied_migrations
    if self.has_table():
       ~~~~~~~~~~~~~~^^
  File "C:\Dev\Gold\gchub_db\.venv\Lib\site-packages\django\db\migrations\recorder.py", line 63, in has_table
    with self.connection.cursor() as cursor:
         ~~~~~~~~~~~~~~~~~~~~~~^^
  File "C:\Dev\Gold\gchub_db\.venv\Lib\site-packages\django\utils\asyncio.py", line 26, in inner
    return func(*args, **kwargs)
  File "C:\Dev\Gold\gchub_db\.venv\Lib\site-packages\django\db\backends\base\base.py", line 320, in cursor
    return self._cursor()
           ~~~~~~~~~~~~^^
  File "C:\Dev\Gold\gchub_db\.venv\Lib\site-packages\django\db\backends\base\base.py", line 296, in _cursor
    self.ensure_connection()
    ~~~~~~~~~~~~~~~~~~~~~~^^
  File "C:\Dev\Gold\gchub_db\.venv\Lib\site-packages\django\utils\asyncio.py", line 26, in inner
    return func(*args, **kwargs)
  File "C:\Dev\Gold\gchub_db\.venv\Lib\site-packages\django\db\backends\base\base.py", line 278, in ensure_connection
    with self.wrap_database_errors:
         ^^^^^^^^^^^^^^^^^^^^^^^^^
  File "C:\Dev\Gold\gchub_db\.venv\Lib\site-packages\django\db\utils.py", line 91, in __exit__
    raise dj_exc_value.with_traceback(traceback) from exc_value
  File "C:\Dev\Gold\gchub_db\.venv\Lib\site-packages\django\db\backends\base\base.py", line 279, in ensure_connection
    self.connect()
    ~~~~~~~~~~~~^^
  File "C:\Dev\Gold\gchub_db\.venv\Lib\site-packages\django\utils\asyncio.py", line 26, in inner
    return func(*args, **kwargs)
  File "C:\Dev\Gold\gchub_db\.venv\Lib\site-packages\django\db\backends\base\base.py", line 256, in connect
    self.connection = self.get_new_connection(conn_params)
                      ~~~~~~~~~~~~~~~~~~~~~~~^^^^^^^^^^^^^
  File "C:\Dev\Gold\gchub_db\.venv\Lib\site-packages\django\utils\asyncio.py", line 26, in inner
    return func(*args, **kwargs)
  File "C:\Dev\Gold\gchub_db\.venv\Lib\site-packages\django\db\backends\postgresql\base.py", line 332, in get_new_connection
    connection = self.Database.connect(**conn_params)
  File "C:\Dev\Gold\gchub_db\.venv\Lib\site-packages\psycopg2\__init__.py", line 135, in connect
    conn = _connect(dsn, connection_factory=connection_factory, **kwasync)
django.db.utils.OperationalError: connection to server at "172.23.8.73", port 5432 failed: Connection timed out (0x0000274C/10060)
	Is the server running on that host and accepting TCP/IP connections?

[restart_app] --- Tail of logs\gchub.log ---
2025-09-01 18:26:50 [DEBUG] gchub_db.apps.auto_corrugated.documents.fsb_box: Font file not found at: /mnt\Production\autocorr_elements\VAG Rounded BT.ttf
2025-09-01 18:26:52 [DEBUG] gchub_db.apps.auto_corrugated.documents.fsb_box: Font file not found at: /mnt\Production\autocorr_elements\VAG Rounded BT.ttf
2025-09-01 18:26:57 [DEBUG] gchub_db.apps.auto_corrugated.documents.fsb_box: Font file not found at: /mnt\Production\autocorr_elements\VAG Rounded BT.ttf
2025-09-01 18:28:29 [DEBUG] gchub_db.apps.auto_corrugated.documents.fsb_box: Font file not found at: /mnt\Production\autocorr_elements\VAG Rounded BT.ttf
2025-09-01 18:30:51 [DEBUG] gchub_db.apps.auto_corrugated.documents.fsb_box: Font file not found at: /mnt\Production\autocorr_elements\VAG Rounded BT.ttf
2025-09-01 18:30:58 [DEBUG] gchub_db.apps.auto_corrugated.documents.fsb_box: Font file not found at: /mnt\Production\autocorr_elements\VAG Rounded BT.ttf
2025-09-01 18:30:59 [DEBUG] gchub_db.apps.auto_corrugated.documents.fsb_box: Font file not found at: /mnt\Production\autocorr_elements\VAG Rounded BT.ttf
2025-09-01 18:31:29 [DEBUG] gchub_db.apps.auto_corrugated.documents.fsb_box: Font file not found at: /mnt\Production\autocorr_elements\VAG Rounded BT.ttf
2025-09-01 18:31:31 [DEBUG] gchub_db.apps.auto_corrugated.documents.fsb_box: Font file not found at: /mnt\Production\autocorr_elements\VAG Rounded BT.ttf
2025-09-01 18:31:33 [DEBUG] gchub_db.apps.auto_corrugated.documents.fsb_box: Font file not found at: /mnt\Production\autocorr_elements\VAG Rounded BT.ttf
2025-09-01 18:32:41 [DEBUG] gchub_db.apps.auto_corrugated.documents.fsb_box: Font file not found at: /mnt\Production\autocorr_elements\VAG Rounded BT.ttf
2025-09-01 18:33:06 [DEBUG] gchub_db.apps.auto_corrugated.documents.fsb_box: Font file not found at: /mnt\Production\autocorr_elements\VAG Rounded BT.ttf
2025-09-01 18:33:08 [DEBUG] gchub_db.apps.auto_corrugated.documents.fsb_box: Font file not found at: /mnt\Production\autocorr_elements\VAG Rounded BT.ttf
2025-09-01 18:33:12 [DEBUG] gchub_db.apps.auto_corrugated.documents.fsb_box: Font file not found at: /mnt\Production\autocorr_elements\VAG Rounded BT.ttf
2025-09-01 18:35:33 [DEBUG] gchub_db.apps.auto_corrugated.documents.fsb_box: Font file not found at: /mnt\Production\autocorr_elements\VAG Rounded BT.ttf
2025-09-01 18:35:34 [DEBUG] gchub_db.apps.auto_corrugated.documents.fsb_box: Font file not found at: /mnt\Production\autocorr_elements\VAG Rounded BT.ttf
2025-09-01 18:35:34 [INFO] django.utils.autoreload: Watching for file changes with StatReloader
2025-09-01 18:35:42 [INFO] django.server: "GET / HTTP/1.1" 200 465
2025-09-01 18:35:42 [INFO] django.server: "GET /media/css/base.css HTTP/1.1" 200 21654
2025-09-01 18:35:42 [INFO] django.server: "GET /media/img/grad_bg.jpg HTTP/1.1" 200 379
2025-09-01 18:35:45 [INFO] django.server: "GET /accounts/login/ HTTP/1.1" 200 4024
2025-09-01 18:35:45 [INFO] django.server: "GET /media/yui/build/base/base-min.css HTTP/1.1" 200 918
2025-09-01 18:35:45 [INFO] django.server: "GET /media/js/general.js HTTP/1.1" 200 1228
2025-09-01 18:35:45 [INFO] django.server: "GET /media/img/gold2logo.png HTTP/1.1" 200 9205
2025-09-01 18:35:45 [INFO] django.server: "GET /media/img/icons/information.png HTTP/1.1" 200 778
2025-09-01 18:35:45 [INFO] django.server: "GET /media/js/prototype.js HTTP/1.1" 200 81469
2025-09-01 18:35:45 [INFO] django.server: "GET /media/css/print.css HTTP/1.1" 200 29
2025-09-01 18:35:53 [INFO] django.server: "GET /accounts/login/ HTTP/1.1" 200 4024
2025-09-01 18:37:15 [DEBUG] gchub_db.apps.auto_corrugated.documents.fsb_box: Font file not found at: /mnt\Production\autocorr_elements\VAG Rounded BT.ttf
2025-09-01 18:37:37 [DEBUG] gchub_db.apps.auto_corrugated.documents.fsb_box: Font file not found at: /mnt\Production\autocorr_elements\VAG Rounded BT.ttf
2025-09-01 18:38:12 [DEBUG] gchub_db.apps.auto_corrugated.documents.fsb_box: Font file not found at: /mnt\Production\autocorr_elements\VAG Rounded BT.ttf
2025-09-01 18:38:14 [DEBUG] gchub_db.apps.auto_corrugated.documents.fsb_box: Font file not found at: /mnt\Production\autocorr_elements\VAG Rounded BT.ttf
[restart_app] Fix migrations / DB issues and re-run the script.
